Workbook

Sheet README
B1: Uncle May's Produce — North Lawndale Food Hub
B2: Steans Family Foundation Financial Model
B3: 3726 W 16th Street, Chicago, IL 60623 | 3,000 sq ft | Black-owned grocery + prepared foods
B4: Prepared: May 2026
B6: STRUCTURE
B7: This workbook is structured around a TWO-PHASE capital deployment:
B8: Phase 1 (Months 1-3): Produce-box delivery launch, ~$250K capital
B9: Phase 2 (Months 4-7+): Retail buildout and operation, ~$500K capital
B10: Phase 2 release is conditional on Phase 1 milestone gates (see 'Milestones' tab).
B12: HOW TO USE
B13: All blue-font cells on the 'Inputs' tab are user-editable assumptions.
B14: Black-font cells are formulas. Do not edit unless you know what you're changing.
... B45: Green font = cross-tab reference

Sheet Inputs
A1: Assumption | B1: Value | C1: Unit | D1: Notes / Source
A2: PROJECT BASICS
A3: Footprint (sq ft) | B3: 3000 | C3: sq ft | D3: 3726 W 16th St, Muldrow space
A4: Phase 1 rent (Months 1-3) | B4: 0 | C4: $/mo | D4: 90-day rent-free per Muldrow MOU
A5: Phase 2 rent subsidized rate | B5: 1 | C5: $/sf/yr | D5: Subsidized for first 12 months post-Phase 2 open
A6: Market rent (Year 2+) | B6: 18 | C6: $/sf/yr | D6: West-side neighborhood retail comp band: $18-$25
A7: Phase 2 open month | B7: 7 | C7: month | D7: Retail floor opens Month 7
A8: PHASE 1 — PRODUCE BOX BUSINESS
A9: Average box price | B9: 50 | C9: $/box | D9: Range $25-$80 per Anthony; $50 mid-point
A10: Box gross margin | B10: 0.25 | C10: % | D10: 25% per Anthony
A11: Boxes per subscriber per month | B11: 4 | C11: boxes | D11: Weekly delivery x 4 weeks
A12: Delivery cost per box | B12: 4.5 | C12: $/box | D12: Variable cost (driver labor, fuel, packaging)
A13: One-time order revenue (% of sub revenue) | B13: 0.3 | C13: % | D13: Non-subscriber walk-up and one-off orders
A14: Monthly subscriber churn | B14: 0.05 | C14: % | D14: 5% monthly = ~46% annual retention; conservative
A15: New subscribers — Month 1 | B15: 25 | C15: subs | D15: Community launch + Pembroke + friends/family
A16: New subscribers — Month 2 | B16: 35 | C16: subs | D16: Word of mouth and outreach
A17: New subscribers — Month 3 | B17: 45 | C17: subs | D17: Tranche 2 gate threshold = 100 active by end of M3
A18: New subscribers — Month 4 | B18: 45 | C18: subs
A19: New subscribers — Month 5 | B19: 45 | C19: subs
A20: New subscribers — Month 6 | B20: 45 | C20: subs
A21: New subscribers — Month 7 | B21: 40 | C21: subs | D21: Retail launch absorbs some attention
A22: New subscribers — Month 8 | B22: 35 | C22: subs
A23: New subscribers — Month 9 | B23: 30 | C23: subs
A24: New subscribers — Month 10 | B24: 25 | C24: subs
A25: New subscribers — Month 11 | B25: 25 | C25: subs
A26: New subscribers — Month 12 | B26: 25 | C26: subs | D26: Steady-state acquisition rate
A27: PHASE 2 — RETAIL
A28: Retail revenue — Month 7 (open) | B28: 40000 | C28: $/mo | D28: Soft open, limited assortment
A29: Retail revenue — Month 8 | B29: 55000 | C29: $/mo
A30: Retail revenue — Month 9 | B30: 70000 | C30: $/mo
A31: Retail revenue — Month 10 | B31: 80000 | C31: $/mo
A32: Retail revenue — Month 11 | B32: 85000 | C32: $/mo
A33: Retail revenue — Month 12 | B33: 90000 | C33: $/mo | D33: Year 1 exit run-rate
A34: Dry grocery — % of retail mix | B34: 0.3 | C34: % | D34: Industry: 35-45%; we run leaner SKU count
A35: Dry grocery — gross margin | B35: 0.26 | C35: % | D35: Industry 25-28%
A36: Produce — % of retail mix | B36: 0.18 | C36: % | D36: Pembroke direct sourcing
A37: Produce — gross margin | B37: 0.42 | C37: % | D37: Industry 38-45% with direct sourcing
A38: Dairy — % of retail mix | B38: 0.08 | C38: %
A39: Dairy — gross margin | B39: 0.3 | C39: %
A40: Meat — % of retail mix | B40: 0.08 | C40: %
...

Sheet Capital Stack
A1: Sources & Uses | B1: Tranche 1 | C1: Tranche 2 | D1: Total | E1: Notes / Instrument
A2: SOURCES
A3: Workforce development grant | B3: =Inputs!$B$81 -> 100000 | C3: =Inputs!$B$82 -> 50000 | D3: =B3+C3 -> 150000 | E3: Steans-aligned: NLW priority is workforce/jobs/economic opportunity
A4: Term debt (subordinated, below-market) | B4: =Inputs!$B$83 -> 100000 | C4: =Inputs!$B$84 -> 350000 | D4: =B4+C4 -> 450000 | E4: PRI-style 6%, 7-year amortization
A5: Subordinated debt (Phase 1 reserve) | B5: =Inputs!$B$85 -> 50000 | C5: 0 | D5: =B5+C5 -> 50000 | E5: Phase 1 cash buffer; below-market PRI-style
A6: Operating reserve (subordinated, Phase 2) | B6: 0 | C6: =Inputs!$B$86 -> 100000 | D6: =B6+C6 -> 100000 | E6: 6-9 months Phase 2 opex; held in cash at Tranche 2 close
A7: Total sources (deployed at close) | B7: =SUM(B3:B6) -> 250000 | C7: =SUM(C3:C6) -> 500000 | D7: =B7+C7 -> 750000
A8: Plus: Line of credit facility (off-balance, drawable) | B8: =Inputs!$B$87 -> 100000 | C8: 0 | D8: =B8+C8 -> 100000 | E8: Revolving facility, draws as needed; not deployed at close
A10: USES — TRANCHE 1 (Phase 1 produce-box launch)
A11: Equipment supplements (delivery, packing, refrig top-up) | B11: 50000 | C11: 0 | D11: =B11+C11 -> 50000 | E11: Subject to equipment audit
A12: Initial inventory (90-day produce + dry goods + packaging) | B12: 70000 | C12: 0 | D12: =B12+C12 -> 70000 | E12: Phase 1 produce + light retail prep
A13: Phase 1 staffing (5-7 FTE x 3-6 months net of grant) | B13: 35000 | C13: 0 | D13: =B13+C13 -> 35000 | E13: Workforce grant absorbs majority
A14: Working capital reserve (Phase 1) | B14: 30000 | C14: 0 | D14: =B14+C14 -> 30000 | E14: CCC drag during ramp
A15: Outreach, marketing, permits, legal | B15: 30000 | C15: 0 | D15: =B15+C15 -> 30000 | E15: Community launch, brand, registrations
A16: Software, POS, ops infrastructure | B16: 20000 | C16: 0 | D16: =B16+C16 -> 20000 | E16: Subscription mgmt, route optimization, basic POS
A17: Tranche 1 contingency (6%) | B17: 15000 | C17: 0 | D17: =B17+C17 -> 15000
A18: Total Tranche 1 uses | B18: =SUM(B11:B17) -> 250000 | C18: =0 -> 0 | D18: =B18+C18 -> 250000
A20: USES — TRANCHE 2 (Phase 2 retail launch)
A21: Retail buildout delta (signage, finish, partitions) | B21: 0 | C21: 130000 | D21: =B21+C21 -> 130000 | E21: Existing equipment offsets vanilla-shell build
A22: Equipment delta (only items not on-site) | B22: 0 | C22: 50000 | D22: =B22+C22 -> 50000 | E22: Subject to equipment audit
A23: Inventory expansion (full retail assortment) | B23: 0 | C23: 100000 | D23: =B23+C23 -> 100000 | E23: Day-1 shelf fill
A24: Phase 2 staffing scale-up (months 7-12 net of grant) | B24: 0 | C24: 100000 | D24: =B24+C24 -> 100000 | E24: Retail launch labor
A25: Operating reserve (6-9 months Phase 2 opex) | B25: 0 | C25: 100000 | D25: =B25+C25 -> 100000 | E25: Critical line; absent in prior model versions
A26: Phase 2 contingency (4%) | B26: 0 | C26: 20000 | D26: =B26+C26 -> 20000
A27: Total Tranche 2 uses | B27: =0 -> 0 | C27: =SUM(C21:C26) -> 500000 | D27: =B27+C27 -> 500000
A29: Total uses | B29: =B18+B27 -> 250000 | C29: =C18+C27 -> 500000 | D29: =B29+C29 -> 750000
A31: Sources less uses (must be zero) | D31: =D7-D29 -> 0

Sheet Phase 1 Revenue
A1: Phase 1 — Produce Box Business | B1: M1 | C1: M2 | D1: M3 | E1: M4 | F1: M5 | G1: M6 | H1: M7 | I1: M8 | J1: M9 | K1: M10 | L1: M11 | M1: M12 | N1: Year 1 Total
A2: New subscribers (gross adds) | B2: =Inputs!$B$15 -> 25 | C2: =Inputs!$B$16 -> 35 | D2: =Inputs!$B$17 -> 45 | E2: =Inputs!$B$18 -> 45 | F2: =Inputs!$B$19 -> 45 | G2: =Inputs!$B$20 -> 45 | H2: =Inputs!$B$21 -> 40 | I2: =Inputs!$B$22 -> 35 | J2: =Inputs!$B$23 -> 30 | K2: =Inputs!$B$24 -> 25 | L2: =Inputs!$B$25 -> 25 | M2: =Inputs!$B$26 -> 25 | N2: =SUM(B2:M2) -> 420
A3: Subscribers churned | B3: =0 -> 0 | C3: =ROUND(B4*Inputs!$B$14,0) -> 1 | D3: =ROUND(C4*Inputs!$B$14,0) -> 3 | E3: =ROUND(D4*Inputs!$B$14,0) -> 5 | F3: =ROUND(E4*Inputs!$B$14,0) -> 7 | G3: =ROUND(F4*Inputs!$B$14,0) -> 9 | H3: =ROUND(G4*Inputs!$B$14,0) -> 11 | I3: =ROUND(H4*Inputs!$B$14,0) -> 12 | J3: =ROUND(I4*Inputs!$B$14,0) -> 13 | ... M3: =ROUND(L4*Inputs!$B$14,0) -> 15 | N3: =SUM(B3:M3) -> 105
A4: Active subscribers (end of month) | B4: =B2-B3 -> 25 | C4: =B4+C2-C3 -> 59 | D4: =C4+D2-D3 -> 101 | E4: =D4+E2-E3 -> 141 | F4: =E4+F2-F3 -> 179 | G4: =F4+G2-G3 -> 215 | H4: =G4+H2-H3 -> 244 | I4: =H4+I2-I3 -> 267 | J4: =I4+J2-J3 -> 284 | ... M4: =L4+M2-M3 -> 315 | N4: =M4 -> 315
A5: Avg active subscribers (this month) | B5: =B4/2 -> 12.5 | C5: =(B4+C4)/2 -> 42 | D5: =(C4+D4)/2 -> 80 | E5: =(D4+E4)/2 -> 121 | F5: =(E4+F4)/2 -> 160 | G5: =(F4+G4)/2 -> 197 | H5: =(G4+H4)/2 -> 229.5 | I5: =(H4+I4)/2 -> 255.5 | J5: =(I4+J4)/2 -> 275.5 | ... M5: =(L4+M4)/2 -> 310
A6: Boxes shipped (subscriber + one-time) | B6: =ROUND(B5*Inputs!$B$11*(1+Inputs!$B$13),0) -> 65 | C6: =ROUND(C5*Inputs!$B$11*(1+Inputs!$B$13),0) -> 218 | D6: =ROUND(D5*Inputs!$B$11*(1+Inputs!$B$13),0) -> 416 | E6: =ROUND(E5*Inputs!$B$11*(1+Inputs!$B$13),0) -> 629 | F6: =ROUND(F5*Inputs!$B$11*(1+Inputs!$B$13),0) -> 832 | G6: =ROUND(G5*Inputs!$B$11*(1+Inputs!$B$13),0) -> 1024 | H6: =ROUND(H5*Inputs!$B$11*(1+Inputs!$B$13),0) -> 1193 | I6: =ROUND(I5*Inputs!$B$11*(1+Inputs!$B$13),0) -> 1329 | ... M6: =ROUND(M5*Inputs!$B$11*(1+Inputs!$B$13),0) -> 1612 | N6: =SUM(B6:M6) -> 11816
A7: Subscription revenue | B7: =B5*Inputs!$B$11*Inputs!$B$9 -> 2500 | C7: =C5*Inputs!$B$11*Inputs!$B$9 -> 8400 | D7: =D5*Inputs!$B$11*Inputs!$B$9 -> 16000 | E7: =E5*Inputs!$B$11*Inputs!$B$9 -> 24200 | F7: =F5*Inputs!$B$11*Inputs!$B$9 -> 32000 | G7: =G5*Inputs!$B$11*Inputs!$B$9 -> 39400 | H7: =H5*Inputs!$B$11*Inputs!$B$9 -> 45900 | I7: =I5*Inputs!$B$11*Inputs!$B$9 -> 51100 | ... M7: =M5*Inputs!$B$11*Inputs!$B$9 -> 62000 | N7: =SUM(B7:M7) -> 454500
A8: One-time order revenue | B8: =B7*Inputs!$B$13 -> 750 | C8: =C7*Inputs!$B$13 -> 2520 | D8: =D7*Inputs!$B$13 -> 4800 | E8: =E7*Inputs!$B$13 -> 7260 | F8: =F7*Inputs!$B$13 -> 9600 | G8: =G7*Inputs!$B$13 -> 11820 | H8: =H7*Inputs!$B$13 -> 13770 | I8: =I7*Inputs!$B$13 -> 15330 | ... M8: =M7*Inputs!$B$13 -> 18600 | N8: =SUM(B8:M8) -> 136350
A9: Total Phase 1 revenue | B9: =B7+B8 -> 3250 | C9: =C7+C8 -> 10920 | D9: =D7+D8 -> 20800 | E9: =E7+E8 -> 31460 | F9: =F7+F8 -> 41600 | G9: =G7+G8 -> 51220 | H9: =H7+H8 -> 59670 | I9: =I7+I8 -> 66430 | ... M9: =M7+M8 -> 80600 | N9: =SUM(B9:M9) -> 590850
A10: COGS (75% of revenue) | B10: =B9*(1-Inputs!$B$10) -> 2437.5 | C10: =C9*(1-Inputs!$B$10) -> 8190 | D10: =D9*(1-Inputs!$B$10) -> 15600 | E10: =E9*(1-Inputs!$B$10) -> 23595 | F10: =F9*(1-Inputs!$B$10) -> 31200 | G10: =G9*(1-Inputs!$B$10) -> 38415 | H10: =H9*(1-Inputs!$B$10) -> 44752.5 | I10: =I9*(1-Inputs!$B$10) -> 49822.5 | ... M10: =M9*(1-Inputs!$B$10) -> 60450 | N10: =SUM(B10:M10) -> 443137.5
A11: Gross profit | B11: =B9-B10 -> 812.5 | C11: =C9-C10 -> 2730 | D11: =D9-D10 -> 5200 | E11: =E9-E10 -> 7865 | F11: =F9-F10 -> 10400 | G11: =G9-G10 -> 12805 | H11: =H9-H10 -> 14917.5 | I11: =I9-I10 -> 16607.5 | ... M11: =M9-M10 -> 20150 | N11: =SUM(B11:M11) -> 147712.5
A12: Delivery cost (driver, fuel, packaging) | B12: =B6*Inputs!$B$12 -> 292.5 | C12: =C6*Inputs!$B$12 -> 981 | D12: =D6*Inputs!$B$12 -> 1872 | E12: =E6*Inputs!$B$12 -> 2830.5 | F12: =F6*Inputs!$B$12 -> 3744 | G12: =G6*Inputs!$B$12 -> 4608 | H12: =H6*Inputs!$B$12 -> 5368.5 | I12: =I6*Inputs!$B$12 -> 5980.5 | ... M12: =M6*Inputs!$B$12 -> 7254 | N12: =SUM(B12:M12) -> 53172
A13: Contribution margin (Phase 1) | B13: =B11-B12 -> 520 | C13: =C11-C12 -> 1749 | D13: =D11-D12 -> 3328 | E13: =E11-E12 -> 5034.5 | F13: =F11-F12 -> 6656 | G13: =G11-G12 -> 8197 | H13: =H11-H12 -> 9549 | I13: =I11-I12 -> 10627 | ... M13: =M11-M12 -> 12896 | N13: =SUM(B13:M13) -> 94540.5
A15: Tranche 2 release gate check (end of Month 3)
A16: Active subscribers at M3 (target: 100+) | B16: =D4 -> 101
A17: M3 monthly revenue (target: $15K-$25K) | B17: =D9 -> 20800

Sheet Phase 2 Revenue
A1: Phase 2 — Retail Floor | B1: M1 | C1: M2 | D1: M3 | E1: M4 | F1: M5 | G1: M6 | H1: M7 | I1: M8 | J1: M9 | K1: M10 | L1: M11 | M1: M12 | N1: Year 1 Total
A2: Total retail revenue | B2: =0 -> 0 | C2: =0 -> 0 | D2: =0 -> 0 | E2: =0 -> 0 | F2: =0 -> 0 | G2: =0 -> 0 | H2: =Inputs!$B$28 -> 40000 | I2: =Inputs!$B$29 -> 55000 | J2: =Inputs!$B$30 -> 70000 | K2: =Inputs!$B$31 -> 80000 | L2: =Inputs!$B$32 -> 85000 | M2: =Inputs!$B$33 -> 90000 | N2: =SUM(B2:M2) -> 420000
A4: Revenue by department (= mix % * total revenue)
A5: Dry grocery (Dry grocery mix) | B5: =B2*Inputs!$B$34 -> 0 | C5: =C2*Inputs!$B$34 -> 0 | D5: =D2*Inputs!$B$34 -> 0 | E5: =E2*Inputs!$B$34 -> 0 | F5: =F2*Inputs!$B$34 -> 0 | G5: =G2*Inputs!$B$34 -> 0 | H5: =H2*Inputs!$B$34 -> 12000 | I5: =I2*Inputs!$B$34 -> 16500 | ... M5: =M2*Inputs!$B$34 -> 27000
A6: Produce (Produce mix) | B6: =B2*Inputs!$B$36 -> 0 | C6: =C2*Inputs!$B$36 -> 0 | D6: =D2*Inputs!$B$36 -> 0 | E6: =E2*Inputs!$B$36 -> 0 | F6: =F2*Inputs!$B$36 -> 0 | G6: =G2*Inputs!$B$36 -> 0 | H6: =H2*Inputs!$B$36 -> 7200 | I6: =I2*Inputs!$B$36 -> 9900 | ... M6: =M2*Inputs!$B$36 -> 16200
A7: Dairy (Dairy mix) | B7: =B2*Inputs!$B$38 -> 0 | C7: =C2*Inputs!$B$38 -> 0 | D7: =D2*Inputs!$B$38 -> 0 | E7: =E2*Inputs!$B$38 -> 0 | F7: =F2*Inputs!$B$38 -> 0 | G7: =G2*Inputs!$B$38 -> 0 | H7: =H2*Inputs!$B$38 -> 3200 | I7: =I2*Inputs!$B$38 -> 4400 | ... M7: =M2*Inputs!$B$38 -> 7200
A8: Meat (Meat mix) | B8: =B2*Inputs!$B$40 -> 0 | C8: =C2*Inputs!$B$40 -> 0 | D8: =D2*Inputs!$B$40 -> 0 | E8: =E2*Inputs!$B$40 -> 0 | F8: =F2*Inputs!$B$40 -> 0 | G8: =G2*Inputs!$B$40 -> 0 | H8: =H2*Inputs!$B$40 -> 3200 | I8: =I2*Inputs!$B$40 -> 4400 | ... M8: =M2*Inputs!$B$40 -> 7200
A9: Frozen (Frozen mix) | B9: =B2*Inputs!$B$42 -> 0 | C9: =C2*Inputs!$B$42 -> 0 | D9: =D2*Inputs!$B$42 -> 0 | E9: =E2*Inputs!$B$42 -> 0 | F9: =F2*Inputs!$B$42 -> 0 | G9: =G2*Inputs!$B$42 -> 0 | H9: =H2*Inputs!$B$42 -> 2400 | I9: =I2*Inputs!$B$42 -> 3300 | ... M9: =M2*Inputs!$B$42 -> 5400
A10: Prepared / hot foods (Prepared / hot foods mix) | B10: =B2*Inputs!$B$44 -> 0 | C10: =C2*Inputs!$B$44 -> 0 | D10: =D2*Inputs!$B$44 -> 0 | E10: =E2*Inputs!$B$44 -> 0 | F10: =F2*Inputs!$B$44 -> 0 | G10: =G2*Inputs!$B$44 -> 0 | H10: =H2*Inputs!$B$44 -> 8000 | I10: =I2*Inputs!$B$44 -> 11000 | ... M10: =M2*Inputs!$B$44 -> 18000
A11: Deli / bakery (Deli / bakery mix) | B11: =B2*Inputs!$B$46 -> 0 | C11: =C2*Inputs!$B$46 -> 0 | D11: =D2*Inputs!$B$46 -> 0 | E11: =E2*Inputs!$B$46 -> 0 | F11: =F2*Inputs!$B$46 -> 0 | G11: =G2*Inputs!$B$46 -> 0 | H11: =H2*Inputs!$B$46 -> 2000 | I11: =I2*Inputs!$B$46 -> 2750 | ... M11: =M2*Inputs!$B$46 -> 4500
A12: Private label (Private label mix) | B12: =B2*Inputs!$B$48 -> 0 | C12: =C2*Inputs!$B$48 -> 0 | D12: =D2*Inputs!$B$48 -> 0 | E12: =E2*Inputs!$B$48 -> 0 | F12: =F2*Inputs!$B$48 -> 0 | G12: =G2*Inputs!$B$48 -> 0 | H12: =H2*Inputs!$B$48 -> 2000 | I12: =I2*Inputs!$B$48 -> 2750 | ... M12: =M2*Inputs!$B$48 -> 4500
A13: Mix check (=100%) | B13: =Inputs!$B$34+Inputs!$B$36+Inputs!$B$38+Inputs!$B$40+Inputs!$B$42+Inputs!$B$44+Inputs!$B$46+Inputs!$B$48 -> 1
A15: COGS by department (= revenue * (1-GM))
A16: Dry grocery COGS | B16: =B5*(1-Inputs!$B$35) -> 0 | C16: =C5*(1-Inputs!$B$35) -> 0 | D16: =D5*(1-Inputs!$B$35) -> 0 | E16: =E5*(1-Inputs!$B$35) -> 0 | F16: =F5*(1-Inputs!$B$35) -> 0 | G16: =G5*(1-Inputs!$B$35) -> 0 | H16: =H5*(1-Inputs!$B$35) -> 8880 | I16: =I5*(1-Inputs!$B$35) -> 12210 | ... M16: =M5*(1-Inputs!$B$35) -> 19980
A17: Produce COGS | B17: =B6*(1-Inputs!$B$37) -> 0 | C17: =C6*(1-Inputs!$B$37) -> 0 | D17: =D6*(1-Inputs!$B$37) -> 0 | E17: =E6*(1-Inputs!$B$37) -> 0 | F17: =F6*(1-Inputs!$B$37) -> 0 | G17: =G6*(1-Inputs!$B$37) -> 0 | H17: =H6*(1-Inputs!$B$37) -> 4176 | I17: =I6*(1-Inputs!$B$37) -> 5742 | ... M17: =M6*(1-Inputs!$B$37) -> 9396
A18: Dairy COGS | B18: =B7*(1-Inputs!$B$39) -> 0 | C18: =C7*(1-Inputs!$B$39) -> 0 | D18: =D7*(1-Inputs!$B$39) -> 0 | E18: =E7*(1-Inputs!$B$39) -> 0 | F18: =F7*(1-Inputs!$B$39) -> 0 | G18: =G7*(1-Inputs!$B$39) -> 0 | H18: =H7*(1-Inputs!$B$39) -> 2240 | I18: =I7*(1-Inputs!$B$39) -> 3080 | ... M18: =M7*(1-Inputs!$B$39) -> 5040
A19: Meat COGS | B19: =B8*(1-Inputs!$B$41) -> 0 | C19: =C8*(1-Inputs!$B$41) -> 0 | D19: =D8*(1-Inputs!$B$41) -> 0 | E19: =E8*(1-Inputs!$B$41) -> 0 | F19: =F8*(1-Inputs!$B$41) -> 0 | G19: =G8*(1-Inputs!$B$41) -> 0 | H19: =H8*(1-Inputs!$B$41) -> 2240 | I19: =I8*(1-Inputs!$B$41) -> 3080 | ... M19: =M8*(1-Inputs!$B$41) -> 5040
A20: Frozen COGS | B20: =B9*(1-Inputs!$B$43) -> 0 | C20: =C9*(1-Inputs!$B$43) -> 0 | D20: =D9*(1-Inputs!$B$43) -> 0 | E20: =E9*(1-Inputs!$B$43) -> 0 | F20: =F9*(1-Inputs!$B$43) -> 0 | G20: =G9*(1-Inputs!$B$43) -> 0 | H20: =H9*(1-Inputs!$B$43) -> 1680 | I20: =I9*(1-Inputs!$B$43) -> 2310 | ... M20: =M9*(1-Inputs!$B$43) -> 3780
A21: Prepared / hot foods COGS | B21: =B10*(1-Inputs!$B$45) -> 0 | C21: =C10*(1-Inputs!$B$45) -> 0 | D21: =D10*(1-Inputs!$B$45) -> 0 | E21: =E10*(1-Inputs!$B$45) -> 0 | F21: =F10*(1-Inputs!$B$45) -> 0 | G21: =G10*(1-Inputs!$B$45) -> 0 | H21: =H10*(1-Inputs!$B$45) -> 4000 | I21: =I10*(1-Inputs!$B$45) -> 5500 | ... M21: =M10*(1-Inputs!$B$45) -> 9000
A22: Deli / bakery COGS | B22: =B11*(1-Inputs!$B$47) -> 0 | C22: =C11*(1-Inputs!$B$47) -> 0 | D22: =D11*(1-Inputs!$B$47) -> 0 | E22: =E11*(1-Inputs!$B$47) -> 0 | F22: =F11*(1-Inputs!$B$47) -> 0 | G22: =G11*(1-Inputs!$B$47) -> 0 | H22: =H11*(1-Inputs!$B$47) -> 1240 | I22: =I11*(1-Inputs!$B$47) -> 1705 | ... M22: =M11*(1-Inputs!$B$47) -> 2790
A23: Private label COGS | B23: =B12*(1-Inputs!$B$49) -> 0 | C23: =C12*(1-Inputs!$B$49) -> 0 | D23: =D12*(1-Inputs!$B$49) -> 0 | E23: =E12*(1-Inputs!$B$49) -> 0 | F23: =F12*(1-Inputs!$B$49) -> 0 | G23: =G12*(1-Inputs!$B$49) -> 0 | H23: =H12*(1-Inputs!$B$49) -> 1100 | I23: =I12*(1-Inputs!$B$49) -> 1512.5 | ... M23: =M12*(1-Inputs!$B$49) -> 2475
A24: Total retail COGS | B24: =SUM(B16:B23) -> 0 | C24: =SUM(C16:C23) -> 0 | D24: =SUM(D16:D23) -> 0 | E24: =SUM(E16:E23) -> 0 | F24: =SUM(F16:F23) -> 0 | G24: =SUM(G16:G23) -> 0 | H24: =SUM(H16:H23) -> 25556 | I24: =SUM(I16:I23) -> 35139.5 | ... M24: =SUM(M16:M23) -> 57501 | N24: =SUM(B24:M24) -> 268338
A25: Total retail gross profit | B25: =B2-B24 -> 0 | C25: =C2-C24 -> 0 | D25: =D2-D24 -> 0 | E25: =E2-E24 -> 0 | F25: =F2-F24 -> 0 | G25: =G2-G24 -> 0 | H25: =H2-H24 -> 14444 | I25: =I2-I24 -> 19860.5 | ... M25: =M2-M24 -> 32499 | N25: =SUM(B25:M25) -> 151662
A26: Blended retail GM % | B26: =IFERROR(B25/B2,0) -> 0 | C26: =IFERROR(C25/C2,0) -> 0 | D26: =IFERROR(D25/D2,0) -> 0 | E26: =IFERROR(E25/E2,0) -> 0 | F26: =IFERROR(F25/F2,0) -> 0 | G26: =IFERROR(G25/G2,0) -> 0 | H26: =IFERROR(H25/H2,0) -> 0.3611 | I26: =IFERROR(I25/I2,0) -> 0.3611 | ... N26: =IFERROR(N25/N2,0) -> 0.3611

Sheet P&L Monthly Y1
A1: P&L (Combined Phase 1 + Phase 2) | B1: M1 | C1: M2 | D1: M3 | E1: M4 | F1: M5 | G1: M6 | H1: M7 | I1: M8 | J1: M9 | K1: M10 | L1: M11 | M1: M12 | N1: Year 1 Total
A2: Revenue
A3: Phase 1 produce-box revenue | B3: ='Phase 1 Revenue'!B9 -> 3250 | C3: ='Phase 1 Revenue'!C9 -> 10920 | D3: ='Phase 1 Revenue'!D9 -> 20800 | E3: ='Phase 1 Revenue'!E9 -> 31460 | F3: ='Phase 1 Revenue'!F9 -> 41600 | G3: ='Phase 1 Revenue'!G9 -> 51220 | H3: ='Phase 1 Revenue'!H9 -> 59670 | I3: ='Phase 1 Revenue'!I9 -> 66430 | ... N3: ='Phase 1 Revenue'!N9 -> 590850
A4: Phase 2 retail revenue | B4: ='Phase 2 Revenue'!B2 -> 0 | C4: ='Phase 2 Revenue'!C2 -> 0 | D4: ='Phase 2 Revenue'!D2 -> 0 | E4: ='Phase 2 Revenue'!E2 -> 0 | F4: ='Phase 2 Revenue'!F2 -> 0 | G4: ='Phase 2 Revenue'!G2 -> 0 | H4: ='Phase 2 Revenue'!H2 -> 40000 | I4: ='Phase 2 Revenue'!I2 -> 55000 | ... N4: ='Phase 2 Revenue'!N2 -> 420000
A5: Total revenue | B5: =B3+B4 -> 3250 | C5: =C3+C4 -> 10920 | D5: =D3+D4 -> 20800 | E5: =E3+E4 -> 31460 | F5: =F3+F4 -> 41600 | G5: =G3+G4 -> 51220 | H5: =H3+H4 -> 99670 | I5: =I3+I4 -> 121430 | ... N5: =N3+N4 -> 1010850
A7: Cost of goods sold
A8: Phase 1 COGS | B8: ='Phase 1 Revenue'!B10 -> 2437.5 | C8: ='Phase 1 Revenue'!C10 -> 8190 | D8: ='Phase 1 Revenue'!D10 -> 15600 | E8: ='Phase 1 Revenue'!E10 -> 23595 | F8: ='Phase 1 Revenue'!F10 -> 31200 | G8: ='Phase 1 Revenue'!G10 -> 38415 | H8: ='Phase 1 Revenue'!H10 -> 44752.5 | I8: ='Phase 1 Revenue'!I10 -> 49822.5 | ... N8: ='Phase 1 Revenue'!N10 -> 443137.5
A9: Phase 2 COGS | B9: ='Phase 2 Revenue'!B24 -> 0 | C9: ='Phase 2 Revenue'!C24 -> 0 | D9: ='Phase 2 Revenue'!D24 -> 0 | E9: ='Phase 2 Revenue'!E24 -> 0 | F9: ='Phase 2 Revenue'!F24 -> 0 | G9: ='Phase 2 Revenue'!G24 -> 0 | H9: ='Phase 2 Revenue'!H24 -> 25556 | I9: ='Phase 2 Revenue'!I24 -> 35139.5 | ... N9: ='Phase 2 Revenue'!N24 -> 268338
A10: Total COGS | B10: =B8+B9 -> 2437.5 | C10: =C8+C9 -> 8190 | D10: =D8+D9 -> 15600 | E10: =E8+E9 -> 23595 | F10: =F8+F9 -> 31200 | G10: =G8+G9 -> 38415 | H10: =H8+H9 -> 70308.5 | I10: =I8+I9 -> 84962 | ... N10: =N8+N9 -> 711475.5
A11: Gross profit | B11: =B5-B10 -> 812.5 | C11: =C5-C10 -> 2730 | D11: =D5-D10 -> 5200 | E11: =E5-E10 -> 7865 | F11: =F5-F10 -> 10400 | G11: =G5-G10 -> 12805 | H11: =H5-H10 -> 29361.5 | I11: =I5-I10 -> 36468 | ... N11: =N5-N10 -> 299374.5
A12: Gross margin % | B12: =IFERROR(B11/B5,0) -> 0.25 | C12: =IFERROR(C11/C5,0) -> 0.25 | D12: =IFERROR(D11/D5,0) -> 0.25 | E12: =IFERROR(E11/E5,0) -> 0.25 | F12: =IFERROR(F11/F5,0) -> 0.25 | G12: =IFERROR(G11/G5,0) -> 0.25 | H12: =IFERROR(H11/H5,0) -> 0.29458714 | I12: =IFERROR(I11/I5,0) -> 0.30032117 | ... N12: =IFERROR(N11/N5,0) -> 0.29616115
A14: Operating expenses
A15: Labor (gross) | B15: =Inputs!$B$61*Inputs!$B$59*Inputs!$B$60 -> 15916 | C15: =Inputs!$B$61*Inputs!$B$59*Inputs!$B$60 -> 15916 | D15: =Inputs!$B$61*Inputs!$B$59*Inputs!$B$60 -> 15916 | E15: =Inputs!$B$62*Inputs!$B$59*Inputs!$B$60 -> 19099.2 | F15: =Inputs!$B$62*Inputs!$B$59*Inputs!$B$60 -> 19099.2 | G15: =Inputs!$B$62*Inputs!$B$59*Inputs!$B$60 -> 19099.2 | H15: =Inputs!$B$63*Inputs!$B$59*Inputs!$B$60 -> 25465.6 | I15: =Inputs!$B$63*Inputs!$B$59*Inputs!$B$60 -> 25465.6 | J15: =Inputs!$B$63*Inputs!$B$59*Inputs!$B$60 -> 25465.6 | K15: =Inputs!$B$64*Inputs!$B$59*Inputs!$B$60 -> 28648.8 | L15: =Inputs!$B$64*Inputs!$B$59*Inputs!$B$60 -> 28648.8 | M15: =Inputs!$B$64*Inputs!$B$59*Inputs!$B$60 -> 28648.8 | N15: =SUM(B15:M15) -> 267388.8
A16: Less: Workforce dev grant offset (amortized) | B16: =$N16/12 -> -12500 | C16: =$N16/12 -> -12500 | D16: =$N16/12 -> -12500 | E16: =$N16/12 -> -12500 | F16: =$N16/12 -> -12500 | G16: =$N16/12 -> -12500 | H16: =$N16/12 -> -12500 | I16: =$N16/12 -> -12500 | ... M16: =$N16/12 -> -12500 | N16: =-(Inputs!$B$81+Inputs!$B$82) -> -150000
A17: Net labor | B17: =B15+B16 -> 3416 | C17: =C15+C16 -> 3416 | D17: =D15+D16 -> 3416 | E17: =E15+E16 -> 6599.2 | F17: =F15+F16 -> 6599.2 | G17: =G15+G16 -> 6599.2 | H17: =H15+H16 -> 12965.6 | I17: =I15+I16 -> 12965.6 | ... N17: =N15+N16 -> 117388.8
A18: Rent (subsidized) | B18: =Inputs!$B$4 -> 0 | C18: =Inputs!$B$4 -> 0 | D18: =Inputs!$B$4 -> 0 | E18: =Inputs!$B$4 -> 0 | F18: =Inputs!$B$4 -> 0 | G18: =Inputs!$B$4 -> 0 | H18: =Inputs!$B$5*Inputs!$B$3/12 -> 250 | I18: =Inputs!$B$5*Inputs!$B$3/12 -> 250 | J18: =Inputs!$B$5*Inputs!$B$3/12 -> 250 | K18: =Inputs!$B$5*Inputs!$B$3/12 -> 250 | L18: =Inputs!$B$5*Inputs!$B$3/12 -> 250 | M18: =Inputs!$B$5*Inputs!$B$3/12 -> 250 | N18: =SUM(B18:M18) -> 1500
A19: Utilities | B19: =Inputs!$B$69 -> 0 | C19: =Inputs!$B$69 -> 0 | D19: =Inputs!$B$69 -> 0 | E19: =Inputs!$B$69 -> 0 | F19: =Inputs!$B$69 -> 0 | G19: =Inputs!$B$69 -> 0 | H19: =Inputs!$B$70 -> 2500 | I19: =Inputs!$B$70 -> 2500 | J19: =Inputs!$B$70 -> 2500 | K19: =Inputs!$B$70 -> 2500 | L19: =Inputs!$B$70 -> 2500 | M19: =Inputs!$B$70 -> 2500 | N19: =SUM(B19:M19) -> 15000
A20: Insurance | B20: =Inputs!$B$71/12 -> 1000 | C20: =Inputs!$B$71/12 -> 1000 | D20: =Inputs!$B$71/12 -> 1000 | E20: =Inputs!$B$71/12 -> 1000 | F20: =Inputs!$B$71/12 -> 1000 | G20: =Inputs!$B$71/12 -> 1000 | H20: =Inputs!$B$71/12 -> 1000 | I20: =Inputs!$B$71/12 -> 1000 | ... M20: =Inputs!$B$71/12 -> 1000 | N20: =SUM(B20:M20) -> 12000
A21: POS / technology | B21: =Inputs!$B$72 -> 600 | C21: =Inputs!$B$72 -> 600 | D21: =Inputs!$B$72 -> 600 | E21: =Inputs!$B$72 -> 600 | F21: =Inputs!$B$72 -> 600 | G21: =Inputs!$B$72 -> 600 | H21: =Inputs!$B$72 -> 600 | I21: =Inputs!$B$72 -> 600 | ... M21: =Inputs!$B$72 -> 600 | N21: =SUM(B21:M21) -> 7200
A22: Cleaning / supplies | B22: =Inputs!$B$73 -> 700 | C22: =Inputs!$B$73 -> 700 | D22: =Inputs!$B$73 -> 700 | E22: =Inputs!$B$73 -> 700 | F22: =Inputs!$B$73 -> 700 | G22: =Inputs!$B$73 -> 700 | H22: =Inputs!$B$73 -> 700 | I22: =Inputs!$B$73 -> 700 | ... M22: =Inputs!$B$73 -> 700 | N22: =SUM(B22:M22) -> 8400
A23: Marketing / outreach | B23: =Inputs!$B$74 -> 2000 | C23: =Inputs!$B$74 -> 2000 | D23: =Inputs!$B$74 -> 2000 | E23: =Inputs!$B$74 -> 2000 | F23: =Inputs!$B$74 -> 2000 | G23: =Inputs!$B$74 -> 2000 | H23: =Inputs!$B$74 -> 2000 | I23: =Inputs!$B$74 -> 2000 | ... M23: =Inputs!$B$74 -> 2000 | N23: =SUM(B23:M23) -> 24000
A24: Vehicle / delivery overhead | B24: =Inputs!$B$75 -> 1500 | C24: =Inputs!$B$75 -> 1500 | D24: =Inputs!$B$75 -> 1500 | E24: =Inputs!$B$75 -> 1500 | F24: =Inputs!$B$75 -> 1500 | G24: =Inputs!$B$75 -> 1500 | H24: =Inputs!$B$75 -> 1500 | I24: =Inputs!$B$75 -> 1500 | ... M24: =Inputs!$B$75 -> 1500 | N24: =SUM(B24:M24) -> 18000
A25: Phase 1 delivery variable cost | B25: ='Phase 1 Revenue'!B12 -> 292.5 | C25: ='Phase 1 Revenue'!C12 -> 981 | D25: ='Phase 1 Revenue'!D12 -> 1872 | E25: ='Phase 1 Revenue'!E12 -> 2830.5 | F25: ='Phase 1 Revenue'!F12 -> 3744 | G25: ='Phase 1 Revenue'!G12 -> 4608 | H25: ='Phase 1 Revenue'!H12 -> 5368.5 | I25: ='Phase 1 Revenue'!I12 -> 5980.5 | ... N25: ='Phase 1 Revenue'!N12 -> 53172
A26: Professional fees | B26: =Inputs!$B$76 -> 800 | C26: =Inputs!$B$76 -> 800 | D26: =Inputs!$B$76 -> 800 | E26: =Inputs!$B$76 -> 800 | F26: =Inputs!$B$76 -> 800 | G26: =Inputs!$B$76 -> 800 | H26: =Inputs!$B$76 -> 800 | I26: =Inputs!$B$76 -> 800 | ... M26: =Inputs!$B$76 -> 800 | N26: =SUM(B26:M26) -> 9600
A27: Shrink / waste (% of retail revenue) | B27: =B4*Inputs!$B$77 -> 0 | C27: =C4*Inputs!$B$77 -> 0 | D27: =D4*Inputs!$B$77 -> 0 | E27: =E4*Inputs!$B$77 -> 0 | F27: =F4*Inputs!$B$77 -> 0 | G27: =G4*Inputs!$B$77 -> 0 | H27: =H4*Inputs!$B$77 -> 1200 | I27: =I4*Inputs!$B$77 -> 1650 | ... N27: =N4*Inputs!$B$77 -> 12600
A28: Total operating expenses | B28: =SUM(B17:B27) -> 10308.5 | C28: =SUM(C17:C27) -> 10997 | D28: =SUM(D17:D27) -> 11888 | E28: =SUM(E17:E27) -> 16029.7 | F28: =SUM(F17:F27) -> 16943.2 | G28: =SUM(G17:G27) -> 17807.2 | H28: =SUM(H17:H27) -> 28884.1 | I28: =SUM(I17:I27) -> 29946.1 | ... N28: =SUM(N17:N27) -> 278860.8
A30: EBITDA | B30: =B11-B28 -> -9496 | C30: =C11-C28 -> -8267 | D30: =D11-D28 -> -6688 | E30: =E11-E28 -> -8164.7 | F30: =F11-F28 -> -6543.2 | G30: =G11-G28 -> -5002.2 | H30: =H11-H28 -> 477.4 | I30: =I11-I28 -> 6521.9 | ... N30: =N11-N28 -> 20513.7
A31: EBITDA margin % | B31: =IFERROR(B30/B5,0) -> -2.9218462 | C31: =IFERROR(C30/C5,0) -> -0.75705128 | D31: =IFERROR(D30/D5,0) -> -0.32153846 | E31: =IFERROR(E30/E5,0) -> -0.25952638 | F31: =IFERROR(F30/F5,0) -> -0.15728846 | G31: =IFERROR(G30/G5,0) -> -0.09766107 | H31: =IFERROR(H30/H5,0) -> 0.0047898064 | I31: =IFERROR(I30/I5,0) -> 0.053709133 | ... N31: =IFERROR(N30/N5,0) -> 0.020293515
A33: Below EBITDA
A34: D&A (estimated, equipment 7-yr SL) | B34: =1200 -> 1200 | C34: =1200 -> 1200 | D34: =1200 -> 1200 | E34: =1200 -> 1200 | F34: =1200 -> 1200 | G34: =1200 -> 1200 | H34: =1200 -> 1200 | I34: =1200 -> 1200 | ... M34: =1200 -> 1200 | N34: =SUM(B34:M34) -> 14400
A35: Interest — term debt | B35: =(Inputs!$B$83+Inputs!$B$84)*Inputs!$B$89/12 -> 2250 | C35: =(Inputs!$B$83+Inputs!$B$84)*Inputs!$B$89/12 -> 2250 | D35: =(Inputs!$B$83+Inputs!$B$84)*Inputs!$B$89/12 -> 2250 | E35: =(Inputs!$B$83+Inputs!$B$84)*Inputs!$B$89/12 -> 2250 | F35: =(Inputs!$B$83+Inputs!$B$84)*Inputs!$B$89/12 -> 2250 | G35: =(Inputs!$B$83+Inputs!$B$84)*Inputs!$B$89/12 -> 2250 | H35: =(Inputs!$B$83+Inputs!$B$84)*Inputs!$B$89/12 -> 2250 | I35: =(Inputs!$B$83+Inputs!$B$84)*Inputs!$B$89/12 -> 2250 | ... M35: =(Inputs!$B$83+Inputs!$B$84)*Inputs!$B$89/12 -> 2250 | N35: =SUM(B35:M35) -> 27000
A36: Interest — line of credit | B36: =Inputs!$B$91*Inputs!$B$88/12 -> 425 | C36: =Inputs!$B$91*Inputs!$B$88/12 -> 425 | D36: =Inputs!$B$91*Inputs!$B$88/12 -> 425 | E36: =Inputs!$B$91*Inputs!$B$88/12 -> 425 | F36: =Inputs!$B$91*Inputs!$B$88/12 -> 425 | G36: =Inputs!$B$91*Inputs!$B$88/12 -> 425 | H36: =Inputs!$B$91*Inputs!$B$88/12 -> 425 | I36: =Inputs!$B$91*Inputs!$B$88/12 -> 425 | ... M36: =Inputs!$B$91*Inputs!$B$88/12 -> 425 | N36: =SUM(B36:M36) -> 5100
A38: Net income (pre-tax) | B38: =B30-B34-B35-B36 -> -13371 | C38: =C30-C34-C35-C36 -> -12142 | D38: =D30-D34-D35-D36 -> -10563 | E38: =E30-E34-E35-E36 -> -12039.7 | F38: =F30-F34-F35-F36 -> -10418.2 | G38: =G30-G34-G35-G36 -> -8877.2 | H38: =H30-H34-H35-H36 -> -3397.6 | I38: =I30-I34-I35-I36 -> 2646.9 | ... N38: =N30-N34-N35-N36 -> -25986.3

Sheet P&L Annual
B1: BASE CASE | G1: DOWNSIDE | L1: STRESS
A2: Annual P&L | B2: Y1 | C2: Y2 | D2: Y3 | E2: Y4 | F2: Y5 | G2: Y1 | H2: Y2 | I2: Y3 | J2: Y4 | K2: Y5 | L2: Y1 | M2: Y2 | N2: Y3 | O2: Y4 | P2: Y5
A4: Revenue
A5: Phase 1 produce-box revenue (base) | B5: ='Phase 1 Revenue'!N9 -> 590850 | C5: =Inputs!$B$54*Inputs!$B$11*Inputs!$B$9*12*(1+Inputs!$B$13) -> 1092000 | D5: =Inputs!$B$55*Inputs!$B$11*Inputs!$B$9*12*(1+Inputs!$B$13) -> 1404000 | E5: =Inputs!$B$56*Inputs!$B$11*Inputs!$B$9*12*(1+Inputs!$B$13) -> 1560000 | F5: =Inputs!$B$57*Inputs!$B$11*Inputs!$B$9*12*(1+Inputs!$B$13) -> 1638000
A6: Phase 2 retail revenue (base) | B6: ='Phase 2 Revenue'!N2 -> 420000 | C6: ='Phase 2 Revenue'!M2*12*(1+Inputs!$B$50) -> 1296000 | D6: =C6*(1+Inputs!$B$51) -> 1490400 | E6: =D6*(1+Inputs!$B$52) -> 1609632 | F6: =E6*(1+Inputs!$B$53) -> 1690113.6
A7: Total revenue (base) | B7: =B5+B6 -> 1010850 | C7: =C5+C6 -> 2388000 | D7: =D5+D6 -> 2894400 | E7: =E5+E6 -> 3169632 | F7: =F5+F6 -> 3328113.6 | G7: =B7*0.85 -> 859222.5 | H7: =C7*0.85 -> 2029800 | I7: =D7*0.85 -> 2460240 | J7: =E7*0.85 -> 2694187.2 | K7: =F7*0.85 -> 2828896.6 | L7: =B7*0.7 -> 707595 | M7: =C7*0.7 -> 1671600 | N7: =D7*0.7 -> 2026080 | O7: =E7*0.7 -> 2218742.4 | P7: =F7*0.7 -> 2329679.5
A9: Gross margin %
A10: Blended GM % | B10: ='P&L Monthly Y1'!N12 -> 0.29616115 | C10: 0.33 | D10: 0.35 | E10: 0.36 | F10: 0.37 | G10: =B10-0.03 -> 0.26616115 | H10: =C10-0.03 -> 0.3 | I10: =D10-0.03 -> 0.32 | J10: =E10-0.03 -> 0.33 | K10: =F10-0.03 -> 0.34 | L10: =B10-0.05 -> 0.24616115 | M10: =C10-0.05 -> 0.28 | N10: =D10-0.05 -> 0.3 | O10: =E10-0.05 -> 0.31 | P10: =F10-0.05 -> 0.32
A11: COGS | B11: =B7*(1-B10) -> 711475.5 | C11: =C7*(1-C10) -> 1599960 | D11: =D7*(1-D10) -> 1881360 | E11: =E7*(1-E10) -> 2028564.5 | F11: =F7*(1-F10) -> 2096711.6 | G11: =G7*(1-G10) -> 630530.85 | H11: =H7*(1-H10) -> 1420860 | I11: =I7*(1-I10) -> 1672963.2 | ... P11: =P7*(1-P10) -> 1584182.1
A12: Gross profit | B12: =B7-B11 -> 299374.5 | C12: =C7-C11 -> 788040 | D12: =D7-D11 -> 1013040 | E12: =E7-E11 -> 1141067.5 | F12: =F7-F11 -> 1231402 | G12: =G7-G11 -> 228691.65 | H12: =H7-H11 -> 608940 | I12: =I7-I11 -> 787276.8 | ... P12: =P7-P11 -> 745497.45
A14: Operating expenses
A15: Labor (loaded, post-grant Y1) | B15: ='P&L Monthly Y1'!N17 -> 117388.8 | C15: =Inputs!$B$65*Inputs!$B$59*Inputs!$B$60*12 -> 420182.4 | D15: =Inputs!$B$66*Inputs!$B$59*Inputs!$B$60*12 -> 458380.8 | E15: =Inputs!$B$67*Inputs!$B$59*Inputs!$B$60*12 -> 496579.2 | F15: =Inputs!$B$68*Inputs!$B$59*Inputs!$B$60*12 -> 534777.6 | G15: =B15 -> 117388.8 | H15: =C15 -> 420182.4 | I15: =D15 -> 458380.8 | J15: =E15 -> 496579.2 | K15: =F15 -> 534777.6 | L15: =B15+L7*0.02 -> 131540.7 | M15: =C15+M7*0.02 -> 453614.4 | N15: =D15+N7*0.02 -> 498902.4 | O15: =E15+O7*0.02 -> 540954.05 | P15: =F15+P7*0.02 -> 581371.19
A16: Rent | B16: ='P&L Monthly Y1'!N18 -> 1500 | C16: =Inputs!$B$6*Inputs!$B$3 -> 54000 | E16: =C16*1.03^(1) -> 55620 | F16: =C16*1.03^(2) -> 57288.6 | G16: =B16 -> 1500 | H16: =C16 -> 54000 | I16: =D16 -> 0 | J16: =E16 -> 55620 | K16: =F16 -> 57288.6 | L16: =B16 -> 1500 | M16: =C16 -> 54000 | N16: =D16 -> 0 | O16: =E16 -> 55620 | P16: =F16 -> 57288.6
A17: Utilities, insurance, POS, supplies, prof fees, vehicle, marketing | B17: ='P&L Monthly Y1'!N19+'P&L Monthly Y1'!N20+'P&L Monthly Y1'!N21+'P&L Monthly Y1'!N22+'P&L Monthly Y1'!N23+'P&L Monthly Y1'!N24+'P&L Monthly Y1'!N25+'P&L Monthly Y1'!N26 -> 147372 | C17: =B17*1.04 -> 153266.88 | D17: =C17*1.04 -> 159397.56 | E17: =D17*1.04 -> 165773.46 | F17: =E17*1.04 -> 172404.4 | G17: =B17 -> 147372 | H17: =C17 -> 153266.88 | I17: =D17 -> 159397.56 | J17: =E17 -> 165773.46 | K17: =F17 -> 172404.4 | L17: =B17 -> 147372 | M17: =C17 -> 153266.88 | N17: =D17 -> 159397.56 | O17: =E17 -> 165773.46 | P17: =F17 -> 172404.4
A18: Shrink / waste | B18: =B6*Inputs!$B$77 -> 12600 | C18: =C6*Inputs!$B$77 -> 38880 | D18: =D6*Inputs!$B$77 -> 44712 | E18: =E6*Inputs!$B$77 -> 48288.96 | F18: =F6*Inputs!$B$77 -> 50703.408 | G18: =G7*Inputs!$B$77*0.6 -> 15466.005 | H18: =H7*Inputs!$B$77*0.6 -> 36536.4 | I18: =I7*Inputs!$B$77*0.6 -> 44284.32 | J18: =J7*Inputs!$B$77*0.6 -> 48495.37 | K18: =K7*Inputs!$B$77*0.6 -> 50920.138 | L18: =L7*(Inputs!$B$77+0.01) -> 28303.8 | M18: =M7*(Inputs!$B$77+0.01) -> 66864 | N18: =N7*(Inputs!$B$77+0.01) -> 81043.2 | O18: =O7*(Inputs!$B$77+0.01) -> 88749.696 | P18: =P7*(Inputs!$B$77+0.01) -> 93187.181
A19: Total opex | B19: =B15+B16+B17+B18 -> 278860.8 | C19: =C15+C16+C17+C18 -> 666329.28 | D19: =D15+D16+D17+D18 -> 662490.36 | E19: =E15+E16+E17+E18 -> 766261.62 | F19: =F15+F16+F17+F18 -> 815174 | G19: =G15+G16+G17+G18 -> 281726.8 | H19: =H15+H16+H17+H18 -> 663985.68 | I19: =I15+I16+I17+I18 -> 662062.68 | ... P19: =P15+P16+P17+P18 -> 904251.37
A21: EBITDA | B21: =B12-B19 -> 20513.7 | C21: =C12-C19 -> 121710.72 | D21: =D12-D19 -> 350549.64 | E21: =E12-E19 -> 374805.9 | F21: =F12-F19 -> 416228.03 | G21: =G12-G19 -> -53035.155 | H21: =H12-H19 -> -55045.68 | I21: =I12-I19 -> 125214.12 | ... P21: =P12-P19 -> -158753.92
A22: EBITDA margin % | B22: =IFERROR(B21/B7,0) -> 0.020293515 | C22: =IFERROR(C21/C7,0) -> 0.050967638 | D22: =IFERROR(D21/D7,0) -> 0.12111306 | E22: =IFERROR(E21/E7,0) -> 0.11824903 | F22: =IFERROR(F21/F7,0) -> 0.12506425 | G22: =IFERROR(G21/G7,0) -> -0.061724588 | H22: =IFERROR(H21/H7,0) -> -0.02711877 | I22: =IFERROR(I21/I7,0) -> 0.050895085 | ... P22: =IFERROR(P21/P7,0) -> -0.068144103
A24: Debt service & coverage
A25: Term debt service (P+I) | B25: =PMT(Inputs!$B$89,Inputs!$B$90,-(Inputs!$B$83+Inputs!$B$84)) -> 80610.758 | C25: =PMT(Inputs!$B$89,Inputs!$B$90,-(Inputs!$B$83+Inputs!$B$84)) -> 80610.758 | D25: =PMT(Inputs!$B$89,Inputs!$B$90,-(Inputs!$B$83+Inputs!$B$84)) -> 80610.758 | E25: =PMT(Inputs!$B$89,Inputs!$B$90,-(Inputs!$B$83+Inputs!$B$84)) -> 80610.758 | F25: =PMT(Inputs!$B$89,Inputs!$B$90,-(Inputs!$B$83+Inputs!$B$84)) -> 80610.758 | G25: =B25 -> 80610.758 | H25: =C25 -> 80610.758 | I25: =D25 -> 80610.758 | J25: =E25 -> 80610.758 | K25: =F25 -> 80610.758 | L25: =B25 -> 80610.758 | M25: =C25 -> 80610.758 | N25: =D25 -> 80610.758 | O25: =E25 -> 80610.758 | P25: =F25 -> 80610.758
A26: LoC interest | B26: =Inputs!$B$91*Inputs!$B$88 -> 5100 | C26: =Inputs!$B$92*Inputs!$B$88 -> 2550 | D26: =Inputs!$B$92*Inputs!$B$88 -> 2550 | E26: =Inputs!$B$92*Inputs!$B$88 -> 2550 | F26: =Inputs!$B$92*Inputs!$B$88 -> 2550 | G26: =B26 -> 5100 | H26: =C26 -> 2550 | I26: =D26 -> 2550 | J26: =E26 -> 2550 | K26: =F26 -> 2550 | L26: =B26 -> 5100 | M26: =C26 -> 2550 | N26: =D26 -> 2550 | O26: =E26 -> 2550 | P26: =F26 -> 2550
A27: Total debt service | B27: =B25+B26 -> 85710.758 | C27: =C25+C26 -> 83160.758 | D27: =D25+D26 -> 83160.758 | E27: =E25+E26 -> 83160.758 | F27: =F25+F26 -> 83160.758 | G27: =G25+G26 -> 85710.758 | H27: =H25+H26 -> 83160.758 | I27: =I25+I26 -> 83160.758 | ... P27: =P25+P26 -> 83160.758
A28: DSCR (EBITDA / debt service) | B28: =IFERROR(B21/B27,0) -> 0.23933635 | C28: =IFERROR(C21/C27,0) -> 1.4635595 | D28: =IFERROR(D21/D27,0) -> 4.2153253 | E28: =IFERROR(E21/E27,0) -> 4.5070044 | F28: =IFERROR(F21/F27,0) -> 5.0051014 | G28: =IFERROR(G21/G27,0) -> -0.61876894 | H28: =IFERROR(H21/H27,0) -> -0.66191893 | I28: =IFERROR(I21/I27,0) -> 1.5056876 | ... P28: =IFERROR(P21/P27,0) -> -1.9090004

Sheet Working Capital
A1: Working Capital & Cash Conversion Cycle | B1: Y1 | C1: Y2 | D1: Y3 | E1: Y4 | F1: Y5
A3: Total revenue | B3: ='P&L Annual'!B7 -> 1010850 | C3: ='P&L Annual'!C7 -> 2388000 | D3: ='P&L Annual'!D7 -> 2894400 | E3: ='P&L Annual'!E7 -> 3169632 | F3: ='P&L Annual'!F7 -> 3328113.6
A4: Total COGS | B4: ='P&L Annual'!B11 -> 711475.5 | C4: ='P&L Annual'!C11 -> 1599960 | D4: ='P&L Annual'!D11 -> 1881360 | E4: ='P&L Annual'!E11 -> 2028564.5 | F4: ='P&L Annual'!F11 -> 2096711.6
A6: Working capital balances (period-end)
A7: Inventory (DIO * COGS / 365) | B7: =B4*Inputs!$B$94/365 -> 48731.199 | C7: =C4*Inputs!$B$95/365 -> 96435.945 | D7: =D4*Inputs!$B$95/365 -> 113397.04 | E7: =E4*Inputs!$B$95/365 -> 122269.64 | F7: =F4*Inputs!$B$95/365 -> 126377.14
A8: Accounts payable (DPO * COGS / 365) | B8: =B4*Inputs!$B$96/365 -> 23390.975 | C8: =C4*Inputs!$B$97/365 -> 109586.3 | D8: =D4*Inputs!$B$97/365 -> 128860.27 | E8: =E4*Inputs!$B$97/365 -> 138942.77 | F8: =F4*Inputs!$B$97/365 -> 143610.38
A9: Accounts receivable (DSO * revenue / 365) | B9: =B3*Inputs!$B$98/365 -> 2769.4521 | C9: =C3*Inputs!$B$98/365 -> 6542.4658 | D9: =D3*Inputs!$B$98/365 -> 7929.863 | E9: =E3*Inputs!$B$98/365 -> 8683.9233 | F9: =F3*Inputs!$B$98/365 -> 9118.1195
A10: Net working capital | B10: =B7-B8+B9 -> 28109.675 | C10: =C7-C8+C9 -> -6607.8904 | D10: =D7-D8+D9 -> -7533.3699 | E10: =E7-E8+E9 -> -7989.2094 | F10: =F7-F8+F9 -> -8115.1263
A12: Cash conversion cycle (DIO + DSO - DPO), days | B12: =Inputs!$B$94+Inputs!$B$98-Inputs!$B$96 -> 14 | C12: =Inputs!$B$95+Inputs!$B$98-Inputs!$B$97 -> -2 | D12: =Inputs!$B$95+Inputs!$B$98-Inputs!$B$97 -> -2 | E12: =Inputs!$B$95+Inputs!$B$98-Inputs!$B$97 -> -2 | F12: =Inputs!$B$95+Inputs!$B$98-Inputs!$B$97 -> -2
A13: Change in NWC (cash impact) | B13: =B10-Inputs!$B$99 -> -71890.325 | C13: =C10-B10 -> -34717.566 | D13: =D10-C10 -> -925.47945 | E13: =E10-D10 -> -455.83956 | F13: =F10-E10 -> -125.91689
A15: Reserve and liquidity coverage
A16: Operating reserve at close | B16: =Inputs!$B$86 -> 100000
A17: Months of opex covered (Y2 stabilized) | B17: =B16/('P&L Annual'!C19/12) -> 1.8009114
A18: LoC facility size | B18: =Inputs!$B$87 -> 100000
A19: Days of COGS covered by LoC | B19: =B18/(C4/365) -> 22.81307

Sheet Debt & DSCR
A1: Debt Schedule & Coverage | B1: Y1 | C1: Y2 | D1: Y3 | E1: Y4 | F1: Y5
A3: Term debt — opening balance | B3: =Inputs!$B$83+Inputs!$B$84 -> 450000 | C3: =B6 -> 396389.24 | D3: =C6 -> 339561.84 | E3: =D6 -> 279324.79 | F3: =E6 -> 215473.52
A4: Annual debt service (P+I) | B4: =PMT(Inputs!$B$89,Inputs!$B$90,-(Inputs!$B$83+Inputs!$B$84)) -> 80610.758 | C4: =PMT(Inputs!$B$89,Inputs!$B$90,-(Inputs!$B$83+Inputs!$B$84)) -> 80610.758 | D4: =PMT(Inputs!$B$89,Inputs!$B$90,-(Inputs!$B$83+Inputs!$B$84)) -> 80610.758 | E4: =PMT(Inputs!$B$89,Inputs!$B$90,-(Inputs!$B$83+Inputs!$B$84)) -> 80610.758 | F4: =PMT(Inputs!$B$89,Inputs!$B$90,-(Inputs!$B$83+Inputs!$B$84)) -> 80610.758
A5: Of which: interest | B5: =B3*Inputs!$B$89 -> 27000 | C5: =C3*Inputs!$B$89 -> 23783.355 | D5: =D3*Inputs!$B$89 -> 20373.71 | E5: =E3*Inputs!$B$89 -> 16759.487 | F5: =F3*Inputs!$B$89 -> 12928.411
A6: Term debt — ending balance | B6: =MAX(0,B3-(B4-B5)) -> 396389.24 | C6: =MAX(0,C3-(C4-C5)) -> 339561.84 | D6: =MAX(0,D3-(D4-D5)) -> 279324.79 | E6: =MAX(0,E3-(E4-E5)) -> 215473.52 | F6: =MAX(0,F3-(F4-F5)) -> 147791.17
A8: Coverage ratios
A9: EBITDA (base case) | B9: ='P&L Annual'!B21 -> 20513.7 | C9: ='P&L Annual'!C21 -> 121710.72 | D9: ='P&L Annual'!D21 -> 350549.64 | E9: ='P&L Annual'!E21 -> 374805.9 | F9: ='P&L Annual'!F21 -> 416228.03
A10: Total debt service | B10: =B4+Inputs!$B$91*Inputs!$B$88 -> 85710.758 | C10: =C4+Inputs!$B$91*Inputs!$B$88 -> 85710.758 | D10: =D4+Inputs!$B$91*Inputs!$B$88 -> 85710.758 | E10: =E4+Inputs!$B$91*Inputs!$B$88 -> 85710.758 | F10: =F4+Inputs!$B$91*Inputs!$B$88 -> 85710.758
A11: DSCR — base case | B11: =IFERROR(B9/B10,0) -> 0.23933635 | C11: =IFERROR(C9/C10,0) -> 1.4200168 | D11: =IFERROR(D9/D10,0) -> 4.0899142 | E11: =IFERROR(E9/E10,0) -> 4.3729155 | F11: =IFERROR(F9/F10,0) -> 4.8561935
A12: DSCR — downside case | B12: =IFERROR('P&L Annual'!G21/B10,0) -> -0.61876894 | C12: =IFERROR('P&L Annual'!H21/C10,0) -> -0.64222603 | D12: =IFERROR('P&L Annual'!I21/D10,0) -> 1.4608916 | E12: =IFERROR('P&L Annual'!J21/E10,0) -> 1.4305526 | F12: =IFERROR('P&L Annual'!K21/F10,0) -> 1.7084681
A13: DSCR — stress case | B13: =IFERROR('P&L Annual'!L21/B10,0) -> -1.5696291 | C13: =IFERROR('P&L Annual'!M21/C10,0) -> -3.0299263 | D13: =IFERROR('P&L Annual'!N21/D10,0) -> -1.5344533 | E13: =IFERROR('P&L Annual'!O21/E10,0) -> -1.9050941 | F13: =IFERROR('P&L Annual'!P21/F10,0) -> -1.8522053
A15: DSCR target (CDFI standard) | B15: ≥ 1.20x stabilized; 1.0x acceptable Y1 if reserves cover

Sheet Sensitivity
A1: Year 2 EBITDA Sensitivity | B1: -20% | C1: -10% | D1: Base | E1: +10% | F1: +20%
A3: Revenue (variable) | B3: ='P&L Annual'!C7*0.8*'P&L Annual'!C10-'P&L Annual'!C19 -> -35897.28 | C3: ='P&L Annual'!C7*0.9*'P&L Annual'!C10-'P&L Annual'!C19 -> 42906.72 | D3: ='P&L Annual'!C7*1*'P&L Annual'!C10-'P&L Annual'!C19 -> 121710.72 | E3: ='P&L Annual'!C7*1.1*'P&L Annual'!C10-'P&L Annual'!C19 -> 200514.72 | F3: ='P&L Annual'!C7*1.2*'P&L Annual'!C10-'P&L Annual'!C19 -> 279318.72
A4: Gross margin (variable, ±3 pts) | B4: ='P&L Annual'!C7*('P&L Annual'!C10+-0.03)-'P&L Annual'!C19 -> 50070.72 | C4: ='P&L Annual'!C7*('P&L Annual'!C10+-0.015)-'P&L Annual'!C19 -> 85890.72 | D4: ='P&L Annual'!C7*('P&L Annual'!C10+0)-'P&L Annual'!C19 -> 121710.72 | E4: ='P&L Annual'!C7*('P&L Annual'!C10+0.015)-'P&L Annual'!C19 -> 157530.72 | F4: ='P&L Annual'!C7*('P&L Annual'!C10+0.03)-'P&L Annual'!C19 -> 193350.72
A5: Labor as % of revenue (variable, ±2 pts) | B5: ='P&L Annual'!C7*'P&L Annual'!C10-'P&L Annual'!C19-'P&L Annual'!C7*0.02 -> 73950.72 | C5: ='P&L Annual'!C7*'P&L Annual'!C10-'P&L Annual'!C19-'P&L Annual'!C7*0.01 -> 97830.72 | D5: ='P&L Annual'!C7*'P&L Annual'!C10-'P&L Annual'!C19-'P&L Annual'!C7*0 -> 121710.72 | E5: ='P&L Annual'!C7*'P&L Annual'!C10-'P&L Annual'!C19-'P&L Annual'!C7*-0.01 -> 145590.72 | F5: ='P&L Annual'!C7*'P&L Annual'!C10-'P&L Annual'!C19-'P&L Annual'!C7*-0.02 -> 169470.72
A7: Two-way sensitivity: Revenue x Gross Margin
A8: Y2 EBITDA | B8: GM 26% | C8: GM 30% | D8: GM 34% (base) | E8: GM 38% | F8: GM 42%
A9: Rev -20% | B9: ='P&L Annual'!C7*0.8*0.26-'P&L Annual'!C19 -> -169625.28 | C9: ='P&L Annual'!C7*0.8*0.3-'P&L Annual'!C19 -> -93209.28 | D9: ='P&L Annual'!C7*0.8*0.34-'P&L Annual'!C19 -> -16793.28 | E9: ='P&L Annual'!C7*0.8*0.38-'P&L Annual'!C19 -> 59622.72 | F9: ='P&L Annual'!C7*0.8*0.42-'P&L Annual'!C19 -> 136038.72
A10: Rev -10% | B10: ='P&L Annual'!C7*0.9*0.26-'P&L Annual'!C19 -> -107537.28 | C10: ='P&L Annual'!C7*0.9*0.3-'P&L Annual'!C19 -> -21569.28 | D10: ='P&L Annual'!C7*0.9*0.34-'P&L Annual'!C19 -> 64398.72 | E10: ='P&L Annual'!C7*0.9*0.38-'P&L Annual'!C19 -> 150366.72 | F10: ='P&L Annual'!C7*0.9*0.42-'P&L Annual'!C19 -> 236334.72
A11: Rev base | B11: ='P&L Annual'!C7*1*0.26-'P&L Annual'!C19 -> -45449.28 | C11: ='P&L Annual'!C7*1*0.3-'P&L Annual'!C19 -> 50070.72 | D11: ='P&L Annual'!C7*1*0.34-'P&L Annual'!C19 -> 145590.72 | E11: ='P&L Annual'!C7*1*0.38-'P&L Annual'!C19 -> 241110.72 | F11: ='P&L Annual'!C7*1*0.42-'P&L Annual'!C19 -> 336630.72
A12: Rev +10% | B12: ='P&L Annual'!C7*1.1*0.26-'P&L Annual'!C19 -> 16638.72 | C12: ='P&L Annual'!C7*1.1*0.3-'P&L Annual'!C19 -> 121710.72 | D12: ='P&L Annual'!C7*1.1*0.34-'P&L Annual'!C19 -> 226782.72 | E12: ='P&L Annual'!C7*1.1*0.38-'P&L Annual'!C19 -> 331854.72 | F12: ='P&L Annual'!C7*1.1*0.42-'P&L Annual'!C19 -> 436926.72
A13: Rev +20% | B13: ='P&L Annual'!C7*1.2*0.26-'P&L Annual'!C19 -> 78726.72 | C13: ='P&L Annual'!C7*1.2*0.3-'P&L Annual'!C19 -> 193350.72 | D13: ='P&L Annual'!C7*1.2*0.34-'P&L Annual'!C19 -> 307974.72 | E13: ='P&L Annual'!C7*1.2*0.38-'P&L Annual'!C19 -> 422598.72 | F13: ='P&L Annual'!C7*1.2*0.42-'P&L Annual'!C19 -> 537222.72

Sheet Milestones
A1: Tranche 2 release gate | B1: Threshold (end of M3) | C1: Verification method | D1: Why Steans cares
A2: Active produce-box subscribers | B2: 100+ weekly subs | C2: Subscription management system export | D2: Demand validation, repeatable revenue, not survey-based intent
A3: Monthly revenue run-rate | B3: $15K - $25K / month | C3: Stripe / payment processor | D3: Operational viability; matches CDFI underwriting Year 1 ramp benchmark
A4: Local hires made | B4: 5 - 7 NLW residents at $16+/hr | C4: Payroll records + zip code attestation | D4: Confirms workforce-development thesis; tied to grant deliverable
A5: EBT acceptance live | B5: Live by Month 2 | C5: USDA SNAP retailer authorization letter | D5: Confirms Steans-priority access mechanism; required for low-income trade area
A6: Pembroke supply contracts | B6: Signed with 3+ farms | C6: Executed supply agreements | D6: Supply chain executable, not aspirational; differentiator from Yellow Banana
A7: Variance to budget | B7: Within 10% of plan | C7: Monthly P&L vs budget reconciliation | D7: Operator financial discipline
A8: Vendor terms earned | B8: Net 14 from 3+ DSD vendors | C8: Vendor account statements | D8: Working capital trajectory improving; reduces reliance on LoC
A12: Tranche 2 release decision matrix
A13: If 7 of 7 gates pass: | B13: Full Tranche 2 release ($500K)
A14: If 5-6 of 7 gates pass: | B14: Conditional release with 30-day cure period for missed gates
A15: If <5 gates pass: | B15: Tranche 2 deferred; operator and funder reassess plan

Sheet Impact
A1: Steans Impact Metric | B1: Y1 | C1: Y2 | D1: Y3 | E1: Y4 | F1: Y5
A2: WORKFORCE
A3: FTE — total | B3: =(Inputs!$B$61*3+Inputs!$B$62*3+Inputs!$B$63*3+Inputs!$B$64*3)/12 -> 7 | C3: =Inputs!$B$65 -> 11 | D3: =Inputs!$B$66 -> 12 | E3: =Inputs!$B$67 -> 13 | F3: =Inputs!$B$68 -> 14
A4: % hires from NLW zip codes (target) | B4: =0.7 -> 0.7 | C4: =0.7 -> 0.7 | D4: =0.7 -> 0.7 | E4: =0.7 -> 0.7 | F4: =0.7 -> 0.7
A5: Hourly wage floor | B5: =16 -> 16 | C5: =16 -> 16 | D5: =16 -> 16 | E5: =16 -> 16 | F5: =16 -> 16
A6: Total annual payroll (NLW residents) | B6: =B3*B4*16*173*12 -> 162758.4 | C6: =C3*C4*16*173*12 -> 255763.2 | D6: =D3*D4*16*173*12 -> 279014.4 | E6: =E3*E4*16*173*12 -> 302265.6 | F6: =F3*F4*16*173*12 -> 325516.8
A8: FOOD ACCESS
A9: Households served / month (subs + retail) | B9: ='Phase 1 Revenue'!M4+ROUND('P&L Annual'!B6/12/45,0)/4 -> 509.5 | C9: =Inputs!$B$54+ROUND('P&L Annual'!C6/12/45,0)/4 -> 950 | D9: =Inputs!$B$55+ROUND('P&L Annual'!D6/12/45,0)/4 -> 1140 | E9: =Inputs!$B$56+ROUND('P&L Annual'!E6/12/45,0)/4 -> 1245.25 | F9: =Inputs!$B$57+ROUND('P&L Annual'!F6/12/45,0)/4 -> 1307.5
A10: SNAP/EBT as % of retail sales (target) | C10: =0.2 -> 0.2 | D10: =0.2 -> 0.2 | E10: =0.2 -> 0.2 | F10: =0.2 -> 0.2
A11: USDA Low Access tract: site at 17031843300 | B11: LILA designated
A13: SUPPLIER NETWORK
A14: Pembroke direct procurement ($) | B14: ='P&L Annual'!B11*0.18*0.3 -> 38419.677 | C14: ='P&L Annual'!C11*0.18*0.3 -> 86397.84 | D14: ='P&L Annual'!D11*0.18*0.3 -> 101593.44 | E14: ='P&L Annual'!E11*0.18*0.3 -> 109542.48 | F14: ='P&L Annual'!F11*0.18*0.3 -> 113222.42
A15: Black-owned vendor procurement ($) | B15: ='P&L Annual'!B11*0.25 -> 177868.88 | C15: ='P&L Annual'!C11*0.25 -> 399990 | D15: ='P&L Annual'!D11*0.25 -> 470340 | E15: ='P&L Annual'!E11*0.25 -> 507141.12 | F15: ='P&L Annual'!F11*0.25 -> 524177.89
A17: LEVERAGE
A18: Steans capital deployed (cumulative) | B18: =Inputs!$B$79 -> 250000 | C18: =Inputs!$B$79+Inputs!$B$80 -> 750000 | D18: =Inputs!$B$79+Inputs!$B$80 -> 750000 | E18: =Inputs!$B$79+Inputs!$B$80 -> 750000 | F18: =Inputs!$B$79+Inputs!$B$80 -> 750000
A19: Total capital deployed (with LoC drawn) | B19: =Inputs!$B$79+Inputs!$B$91 -> 310000 | C19: =Inputs!$B$79+Inputs!$B$80+Inputs!$B$92 -> 780000 | D19: =Inputs!$B$79+Inputs!$B$80+Inputs!$B$92 -> 780000 | E19: =Inputs!$B$79+Inputs!$B$80+Inputs!$B$92 -> 780000 | F19: =Inputs!$B$79+Inputs!$B$80+Inputs!$B$92 -> 780000
A20: Cumulative revenue generated | B20: ='P&L Annual'!B7 -> 1010850 | C20: =B20+'P&L Annual'!C7 -> 3398850 | D20: =C20+'P&L Annual'!D7 -> 6293250 | E20: =D20+'P&L Annual'!E7 -> 9462882 | F20: =E20+'P&L Annual'!F7 -> 12790996
A21: Revenue per dollar of Steans capital (cumulative) | B21: =B20/B18 -> 4.0434 | C21: =C20/C18 -> 4.5318 | D21: =D20/D18 -> 8.391 | E21: =E20/E18 -> 12.617176 | F21: =F20/F18 -> 17.054661
